2020-05-05 00:20:34,775 -  nornir.core -     INFO -        run() - Running task 'basic_configuration' with args {'template_name': 'ntp.j2'} on 2 hosts
2020-05-05 00:20:34,788 - nornir.core.task -    ERROR -      start() - Host 'r1': task 'Base Configuration' failed with traceback:
Traceback (most recent call last):
  File "/home/gns3/.local/lib/python3.6/site-packages/nornir/core/task.py", line 85, in start
    r = self.task(self, **self.params)
  File "/home/gns3/.local/lib/python3.6/site-packages/nornir/plugins/tasks/text/template_file.py", line 35, in template_file
    **kwargs
  File "/home/gns3/.local/lib/python3.6/site-packages/nornir/core/helpers/jinja_helper.py", line 17, in render_from_file
    t = env.get_template(template)
  File "/home/gns3/.local/lib/python3.6/site-packages/jinja2/environment.py", line 883, in get_template
    return self._load_template(name, self.make_globals(globals))
  File "/home/gns3/.local/lib/python3.6/site-packages/jinja2/environment.py", line 857, in _load_template
    template = self.loader.load(self, name, globals)
  File "/home/gns3/.local/lib/python3.6/site-packages/jinja2/loaders.py", line 115, in load
    source, filename, uptodate = self.get_source(environment, name)
  File "/home/gns3/.local/lib/python3.6/site-packages/jinja2/loaders.py", line 197, in get_source
    raise TemplateNotFound(template)
jinja2.exceptions.TemplateNotFound: ntp.j2

2020-05-05 00:20:34,788 - nornir.core.task -    ERROR -      start() - Host 'r1': task 'basic_configuration' failed with traceback:
Traceback (most recent call last):
  File "/home/gns3/.local/lib/python3.6/site-packages/nornir/core/task.py", line 85, in start
    r = self.task(self, **self.params)
  File "deploy_configs.py", line 11, in basic_configuration
    path=f"templates/{task.host.platform}")
  File "/home/gns3/.local/lib/python3.6/site-packages/nornir/core/task.py", line 147, in run
    raise NornirSubTaskError(task=task, result=r)
nornir.core.exceptions.NornirSubTaskError: Subtask: <function template_file at 0x7f9b40524950> (failed)


2020-05-05 00:20:34,789 - nornir.core.task -    ERROR -      start() - Host 'r2': task 'Base Configuration' failed with traceback:
Traceback (most recent call last):
  File "/home/gns3/.local/lib/python3.6/site-packages/nornir/core/task.py", line 85, in start
    r = self.task(self, **self.params)
  File "/home/gns3/.local/lib/python3.6/site-packages/nornir/plugins/tasks/text/template_file.py", line 35, in template_file
    **kwargs
  File "/home/gns3/.local/lib/python3.6/site-packages/nornir/core/helpers/jinja_helper.py", line 17, in render_from_file
    t = env.get_template(template)
  File "/home/gns3/.local/lib/python3.6/site-packages/jinja2/environment.py", line 883, in get_template
    return self._load_template(name, self.make_globals(globals))
  File "/home/gns3/.local/lib/python3.6/site-packages/jinja2/environment.py", line 857, in _load_template
    template = self.loader.load(self, name, globals)
  File "/home/gns3/.local/lib/python3.6/site-packages/jinja2/loaders.py", line 115, in load
    source, filename, uptodate = self.get_source(environment, name)
  File "/home/gns3/.local/lib/python3.6/site-packages/jinja2/loaders.py", line 197, in get_source
    raise TemplateNotFound(template)
jinja2.exceptions.TemplateNotFound: ntp.j2

2020-05-05 00:20:34,789 - nornir.core.task -    ERROR -      start() - Host 'r2': task 'basic_configuration' failed with traceback:
Traceback (most recent call last):
  File "/home/gns3/.local/lib/python3.6/site-packages/nornir/core/task.py", line 85, in start
    r = self.task(self, **self.params)
  File "deploy_configs.py", line 11, in basic_configuration
    path=f"templates/{task.host.platform}")
  File "/home/gns3/.local/lib/python3.6/site-packages/nornir/core/task.py", line 147, in run
    raise NornirSubTaskError(task=task, result=r)
nornir.core.exceptions.NornirSubTaskError: Subtask: <function template_file at 0x7f9b40524950> (failed)


2020-05-05 00:21:22,095 -  nornir.core -     INFO -        run() - Running task 'basic_configuration' with args {'template_name': 'ntp.j2'} on 2 hosts
2020-05-05 00:21:22,104 - nornir.core.task -    ERROR -      start() - Host 'r1': task 'Base Configuration' failed with traceback:
Traceback (most recent call last):
  File "/home/gns3/.local/lib/python3.6/site-packages/nornir/core/task.py", line 85, in start
    r = self.task(self, **self.params)
  File "/home/gns3/.local/lib/python3.6/site-packages/nornir/plugins/tasks/text/template_file.py", line 35, in template_file
    **kwargs
  File "/home/gns3/.local/lib/python3.6/site-packages/nornir/core/helpers/jinja_helper.py", line 18, in render_from_file
    return t.render(**kwargs)
  File "/home/gns3/.local/lib/python3.6/site-packages/jinja2/environment.py", line 1090, in render
    self.environment.handle_exception()
  File "/home/gns3/.local/lib/python3.6/site-packages/jinja2/environment.py", line 832, in handle_exception
    reraise(*rewrite_traceback_stack(source=source))
  File "/home/gns3/.local/lib/python3.6/site-packages/jinja2/_compat.py", line 28, in reraise
    raise value.with_traceback(tb)
  File "../templates/junos/ntp.j2", line 5, in top-level template code
    {% for server in host.ntp_servers %}
jinja2.exceptions.UndefinedError: 'nornir.core.inventory.Host object' has no attribute 'ntp_servers'

2020-05-05 00:21:22,105 - nornir.core.task -    ERROR -      start() - Host 'r1': task 'basic_configuration' failed with traceback:
Traceback (most recent call last):
  File "/home/gns3/.local/lib/python3.6/site-packages/nornir/core/task.py", line 85, in start
    r = self.task(self, **self.params)
  File "deploy_configs.py", line 11, in basic_configuration
    path=f"../templates/{task.host.platform}")
  File "/home/gns3/.local/lib/python3.6/site-packages/nornir/core/task.py", line 147, in run
    raise NornirSubTaskError(task=task, result=r)
nornir.core.exceptions.NornirSubTaskError: Subtask: <function template_file at 0x7ff0c7f7a950> (failed)


2020-05-05 00:21:22,107 - nornir.core.task -    ERROR -      start() - Host 'r2': task 'Base Configuration' failed with traceback:
Traceback (most recent call last):
  File "/home/gns3/.local/lib/python3.6/site-packages/nornir/core/task.py", line 85, in start
    r = self.task(self, **self.params)
  File "/home/gns3/.local/lib/python3.6/site-packages/nornir/plugins/tasks/text/template_file.py", line 35, in template_file
    **kwargs
  File "/home/gns3/.local/lib/python3.6/site-packages/nornir/core/helpers/jinja_helper.py", line 18, in render_from_file
    return t.render(**kwargs)
  File "/home/gns3/.local/lib/python3.6/site-packages/jinja2/environment.py", line 1090, in render
    self.environment.handle_exception()
  File "/home/gns3/.local/lib/python3.6/site-packages/jinja2/environment.py", line 832, in handle_exception
    reraise(*rewrite_traceback_stack(source=source))
  File "/home/gns3/.local/lib/python3.6/site-packages/jinja2/_compat.py", line 28, in reraise
    raise value.with_traceback(tb)
  File "../templates/junos/ntp.j2", line 5, in top-level template code
    {% for server in host.ntp_servers %}
jinja2.exceptions.UndefinedError: 'nornir.core.inventory.Host object' has no attribute 'ntp_servers'

2020-05-05 00:21:22,107 - nornir.core.task -    ERROR -      start() - Host 'r2': task 'basic_configuration' failed with traceback:
Traceback (most recent call last):
  File "/home/gns3/.local/lib/python3.6/site-packages/nornir/core/task.py", line 85, in start
    r = self.task(self, **self.params)
  File "deploy_configs.py", line 11, in basic_configuration
    path=f"../templates/{task.host.platform}")
  File "/home/gns3/.local/lib/python3.6/site-packages/nornir/core/task.py", line 147, in run
    raise NornirSubTaskError(task=task, result=r)
nornir.core.exceptions.NornirSubTaskError: Subtask: <function template_file at 0x7ff0c7f7a950> (failed)


2020-05-05 00:21:58,568 -  nornir.core -     INFO -        run() - Running task 'basic_configuration' with args {'template_name': 'interfaces.j2'} on 2 hosts
2020-05-05 00:21:58,585 - nornir.core.task -    ERROR -      start() - Host 'r1': task 'Base Configuration' failed with traceback:
Traceback (most recent call last):
  File "/home/gns3/.local/lib/python3.6/site-packages/nornir/core/task.py", line 85, in start
    r = self.task(self, **self.params)
  File "/home/gns3/.local/lib/python3.6/site-packages/nornir/plugins/tasks/text/template_file.py", line 35, in template_file
    **kwargs
  File "/home/gns3/.local/lib/python3.6/site-packages/nornir/core/helpers/jinja_helper.py", line 18, in render_from_file
    return t.render(**kwargs)
  File "/home/gns3/.local/lib/python3.6/site-packages/jinja2/environment.py", line 1090, in render
    self.environment.handle_exception()
  File "/home/gns3/.local/lib/python3.6/site-packages/jinja2/environment.py", line 832, in handle_exception
    reraise(*rewrite_traceback_stack(source=source))
  File "/home/gns3/.local/lib/python3.6/site-packages/jinja2/_compat.py", line 28, in reraise
    raise value.with_traceback(tb)
  File "../templates/junos/interfaces.j2", line 3, in top-level template code
    {% for intf, unit_dict in interface_dict.items() %}
jinja2.exceptions.UndefinedError: 'str object' has no attribute 'items'

2020-05-05 00:21:58,585 - nornir.core.task -    ERROR -      start() - Host 'r1': task 'basic_configuration' failed with traceback:
Traceback (most recent call last):
  File "/home/gns3/.local/lib/python3.6/site-packages/nornir/core/task.py", line 85, in start
    r = self.task(self, **self.params)
  File "deploy_configs.py", line 11, in basic_configuration
    path=f"../templates/{task.host.platform}")
  File "/home/gns3/.local/lib/python3.6/site-packages/nornir/core/task.py", line 147, in run
    raise NornirSubTaskError(task=task, result=r)
nornir.core.exceptions.NornirSubTaskError: Subtask: <function template_file at 0x7f76a29ac950> (failed)


2020-05-05 00:21:58,596 - nornir.core.task -    ERROR -      start() - Host 'r2': task 'Base Configuration' failed with traceback:
Traceback (most recent call last):
  File "/home/gns3/.local/lib/python3.6/site-packages/nornir/core/task.py", line 85, in start
    r = self.task(self, **self.params)
  File "/home/gns3/.local/lib/python3.6/site-packages/nornir/plugins/tasks/text/template_file.py", line 35, in template_file
    **kwargs
  File "/home/gns3/.local/lib/python3.6/site-packages/nornir/core/helpers/jinja_helper.py", line 18, in render_from_file
    return t.render(**kwargs)
  File "/home/gns3/.local/lib/python3.6/site-packages/jinja2/environment.py", line 1090, in render
    self.environment.handle_exception()
  File "/home/gns3/.local/lib/python3.6/site-packages/jinja2/environment.py", line 832, in handle_exception
    reraise(*rewrite_traceback_stack(source=source))
  File "/home/gns3/.local/lib/python3.6/site-packages/jinja2/_compat.py", line 28, in reraise
    raise value.with_traceback(tb)
  File "../templates/junos/interfaces.j2", line 3, in top-level template code
    {% for intf, unit_dict in interface_dict.items() %}
jinja2.exceptions.UndefinedError: 'str object' has no attribute 'items'

2020-05-05 00:21:58,596 - nornir.core.task -    ERROR -      start() - Host 'r2': task 'basic_configuration' failed with traceback:
Traceback (most recent call last):
  File "/home/gns3/.local/lib/python3.6/site-packages/nornir/core/task.py", line 85, in start
    r = self.task(self, **self.params)
  File "deploy_configs.py", line 11, in basic_configuration
    path=f"../templates/{task.host.platform}")
  File "/home/gns3/.local/lib/python3.6/site-packages/nornir/core/task.py", line 147, in run
    raise NornirSubTaskError(task=task, result=r)
nornir.core.exceptions.NornirSubTaskError: Subtask: <function template_file at 0x7f76a29ac950> (failed)


2020-05-05 13:17:06,974 -  nornir.core -     INFO -        run() - Running task 'basic_configuration' with args {'template_name': 'ntp.j2'} on 2 hosts
2020-05-05 13:17:06,991 - nornir.core.task -    ERROR -      start() - Host 'r1': task 'Base Configuration' failed with traceback:
Traceback (most recent call last):
  File "/home/gns3/.local/lib/python3.6/site-packages/nornir/core/task.py", line 85, in start
    r = self.task(self, **self.params)
  File "/home/gns3/.local/lib/python3.6/site-packages/nornir/plugins/tasks/text/template_file.py", line 35, in template_file
    **kwargs
  File "/home/gns3/.local/lib/python3.6/site-packages/nornir/core/helpers/jinja_helper.py", line 18, in render_from_file
    return t.render(**kwargs)
  File "/home/gns3/.local/lib/python3.6/site-packages/jinja2/environment.py", line 1090, in render
    self.environment.handle_exception()
  File "/home/gns3/.local/lib/python3.6/site-packages/jinja2/environment.py", line 832, in handle_exception
    reraise(*rewrite_traceback_stack(source=source))
  File "/home/gns3/.local/lib/python3.6/site-packages/jinja2/_compat.py", line 28, in reraise
    raise value.with_traceback(tb)
  File "../templates/junos/ntp.j2", line 5, in top-level template code
    {% for server in host.ntp_servers %}
jinja2.exceptions.UndefinedError: 'nornir.core.inventory.Host object' has no attribute 'ntp_servers'

2020-05-05 13:17:06,992 - nornir.core.task -    ERROR -      start() - Host 'r1': task 'basic_configuration' failed with traceback:
Traceback (most recent call last):
  File "/home/gns3/.local/lib/python3.6/site-packages/nornir/core/task.py", line 85, in start
    r = self.task(self, **self.params)
  File "deploy_configs.py", line 11, in basic_configuration
    path=f"../templates/{task.host.platform}")
  File "/home/gns3/.local/lib/python3.6/site-packages/nornir/core/task.py", line 147, in run
    raise NornirSubTaskError(task=task, result=r)
nornir.core.exceptions.NornirSubTaskError: Subtask: <function template_file at 0x7f4ac5323950> (failed)


2020-05-05 13:17:06,994 - nornir.core.task -    ERROR -      start() - Host 'r2': task 'Base Configuration' failed with traceback:
Traceback (most recent call last):
  File "/home/gns3/.local/lib/python3.6/site-packages/nornir/core/task.py", line 85, in start
    r = self.task(self, **self.params)
  File "/home/gns3/.local/lib/python3.6/site-packages/nornir/plugins/tasks/text/template_file.py", line 35, in template_file
    **kwargs
  File "/home/gns3/.local/lib/python3.6/site-packages/nornir/core/helpers/jinja_helper.py", line 18, in render_from_file
    return t.render(**kwargs)
  File "/home/gns3/.local/lib/python3.6/site-packages/jinja2/environment.py", line 1090, in render
    self.environment.handle_exception()
  File "/home/gns3/.local/lib/python3.6/site-packages/jinja2/environment.py", line 832, in handle_exception
    reraise(*rewrite_traceback_stack(source=source))
  File "/home/gns3/.local/lib/python3.6/site-packages/jinja2/_compat.py", line 28, in reraise
    raise value.with_traceback(tb)
  File "../templates/junos/ntp.j2", line 5, in top-level template code
    {% for server in host.ntp_servers %}
jinja2.exceptions.UndefinedError: 'nornir.core.inventory.Host object' has no attribute 'ntp_servers'

2020-05-05 13:17:06,994 - nornir.core.task -    ERROR -      start() - Host 'r2': task 'basic_configuration' failed with traceback:
Traceback (most recent call last):
  File "/home/gns3/.local/lib/python3.6/site-packages/nornir/core/task.py", line 85, in start
    r = self.task(self, **self.params)
  File "deploy_configs.py", line 11, in basic_configuration
    path=f"../templates/{task.host.platform}")
  File "/home/gns3/.local/lib/python3.6/site-packages/nornir/core/task.py", line 147, in run
    raise NornirSubTaskError(task=task, result=r)
nornir.core.exceptions.NornirSubTaskError: Subtask: <function template_file at 0x7f4ac5323950> (failed)


2020-05-05 13:18:41,005 -  nornir.core -     INFO -        run() - Running task 'basic_configuration' with args {'template_name': 'interfaces.j2'} on 2 hosts
2020-05-05 13:18:41,014 - nornir.core.task -    ERROR -      start() - Host 'r1': task 'Base Configuration' failed with traceback:
Traceback (most recent call last):
  File "/home/gns3/.local/lib/python3.6/site-packages/nornir/core/task.py", line 85, in start
    r = self.task(self, **self.params)
  File "/home/gns3/.local/lib/python3.6/site-packages/nornir/plugins/tasks/text/template_file.py", line 35, in template_file
    **kwargs
  File "/home/gns3/.local/lib/python3.6/site-packages/nornir/core/helpers/jinja_helper.py", line 18, in render_from_file
    return t.render(**kwargs)
  File "/home/gns3/.local/lib/python3.6/site-packages/jinja2/environment.py", line 1090, in render
    self.environment.handle_exception()
  File "/home/gns3/.local/lib/python3.6/site-packages/jinja2/environment.py", line 832, in handle_exception
    reraise(*rewrite_traceback_stack(source=source))
  File "/home/gns3/.local/lib/python3.6/site-packages/jinja2/_compat.py", line 28, in reraise
    raise value.with_traceback(tb)
  File "../templates/junos/interfaces.j2", line 3, in top-level template code
    {% for intf, unit_dict in interface_dict.items() %}
jinja2.exceptions.UndefinedError: 'str object' has no attribute 'items'

2020-05-05 13:18:41,015 - nornir.core.task -    ERROR -      start() - Host 'r1': task 'basic_configuration' failed with traceback:
Traceback (most recent call last):
  File "/home/gns3/.local/lib/python3.6/site-packages/nornir/core/task.py", line 85, in start
    r = self.task(self, **self.params)
  File "deploy_configs.py", line 11, in basic_configuration
    path=f"../templates/{task.host.platform}")
  File "/home/gns3/.local/lib/python3.6/site-packages/nornir/core/task.py", line 147, in run
    raise NornirSubTaskError(task=task, result=r)
nornir.core.exceptions.NornirSubTaskError: Subtask: <function template_file at 0x7f92a12e9950> (failed)


2020-05-05 13:18:41,020 - nornir.core.task -    ERROR -      start() - Host 'r2': task 'Base Configuration' failed with traceback:
Traceback (most recent call last):
  File "/home/gns3/.local/lib/python3.6/site-packages/nornir/core/task.py", line 85, in start
    r = self.task(self, **self.params)
  File "/home/gns3/.local/lib/python3.6/site-packages/nornir/plugins/tasks/text/template_file.py", line 35, in template_file
    **kwargs
  File "/home/gns3/.local/lib/python3.6/site-packages/nornir/core/helpers/jinja_helper.py", line 18, in render_from_file
    return t.render(**kwargs)
  File "/home/gns3/.local/lib/python3.6/site-packages/jinja2/environment.py", line 1090, in render
    self.environment.handle_exception()
  File "/home/gns3/.local/lib/python3.6/site-packages/jinja2/environment.py", line 832, in handle_exception
    reraise(*rewrite_traceback_stack(source=source))
  File "/home/gns3/.local/lib/python3.6/site-packages/jinja2/_compat.py", line 28, in reraise
    raise value.with_traceback(tb)
  File "../templates/junos/interfaces.j2", line 3, in top-level template code
    {% for intf, unit_dict in interface_dict.items() %}
jinja2.exceptions.UndefinedError: 'str object' has no attribute 'items'

2020-05-05 13:18:41,020 - nornir.core.task -    ERROR -      start() - Host 'r2': task 'basic_configuration' failed with traceback:
Traceback (most recent call last):
  File "/home/gns3/.local/lib/python3.6/site-packages/nornir/core/task.py", line 85, in start
    r = self.task(self, **self.params)
  File "deploy_configs.py", line 11, in basic_configuration
    path=f"../templates/{task.host.platform}")
  File "/home/gns3/.local/lib/python3.6/site-packages/nornir/core/task.py", line 147, in run
    raise NornirSubTaskError(task=task, result=r)
nornir.core.exceptions.NornirSubTaskError: Subtask: <function template_file at 0x7f92a12e9950> (failed)


2020-05-05 17:27:16,099 -  nornir.core -     INFO -        run() - Running task 'napalm_get' with args {'getters': ['config']} on 2 hosts
2020-05-05 17:28:09,328 -  nornir.core -     INFO -        run() - Running task 'napalm_get' with args {'getters': ['facts']} on 2 hosts
2020-05-05 17:29:10,361 -  nornir.core -     INFO -        run() - Running task 'napalm_get' with args {'getters': ['config']} on 2 hosts
2020-05-05 17:29:11,750 -  nornir.core -     INFO -        run() - Running task 'napalm_get' with args {'getters': ['facts']} on 2 hosts
2020-05-06 12:33:10,478 -  nornir.core -     INFO -        run() - Running task 'push_config' with args {'template': 'interfaces.j2'} on 2 hosts
2020-05-06 12:43:34,614 -  nornir.core -     INFO -        run() - Running task 'push_config' with args {'template': 'interfaces.j2'} on 2 hosts
2020-05-06 12:44:21,623 -  nornir.core -     INFO -        run() - Running task 'push_config' with args {'template': 'interfaces.j2'} on 2 hosts
2020-05-06 12:49:33,974 -  nornir.core -  WARNING -        run() - Task 'basic_configuration' has not been run – 0 hosts selected
2020-05-06 12:52:13,718 -  nornir.core -  WARNING -        run() - Task 'basic_configuration' has not been run – 0 hosts selected
2020-05-06 12:54:59,278 -  nornir.core -     INFO -        run() - Running task 'push_config' with args {'template': 'interfaces.j2'} on 2 hosts
2020-05-06 12:55:19,819 -  nornir.core -     INFO -        run() - Running task 'push_config' with args {'template': 'ntp.j2'} on 2 hosts
2020-05-06 12:56:08,393 -  nornir.core -     INFO -        run() - Running task 'push_config' with args {'template': 'dns.j2'} on 2 hosts
2020-05-06 12:56:24,943 -  nornir.core -     INFO -        run() - Running task 'push_config' with args {'template': 'system.j2'} on 2 hosts
2020-05-06 12:57:32,439 -  nornir.core -     INFO -        run() - Running task 'push_config' with args {'template': 'all.j2'} on 2 hosts
2020-05-06 16:46:12,998 -  nornir.core -     INFO -        run() - Running task 'push_config' with args {'template': 'all.j2'} on 2 hosts
2020-05-06 17:17:15,670 -  nornir.core -     INFO -        run() - Running task 'push_config' with args {'template': 'all.j2'} on 2 hosts
2020-05-06 17:19:57,378 -  nornir.core -     INFO -        run() - Running task 'push_config' with args {'template': 'all.j2'} on 2 hosts
2020-05-06 18:33:02,361 -  nornir.core -     INFO -        run() - Running task 'napalm_validate' with args {'src': '../validators/validate.yaml'} on 2 hosts
2020-05-06 18:33:03,257 - nornir.core.task -    ERROR -      start() - Host 'r1': task 'napalm_validate' failed with traceback:
Traceback (most recent call last):
  File "/home/gns3/virtualvenvs/nornir/lib/python3.6/site-packages/napalm/base/validate.py", line 23, in _get_validation_file
    with open(validation_file, "r") as stream:
FileNotFoundError: [Errno 2] No such file or directory: '../validators/validate.yaml'

During handling of the above exception, another exception occurred:

Traceback (most recent call last):
  File "/home/gns3/virtualvenvs/nornir/lib/python3.6/site-packages/nornir/core/task.py", line 85, in start
    r = self.task(self, **self.params)
  File "/home/gns3/virtualvenvs/nornir/lib/python3.6/site-packages/nornir/plugins/tasks/networking/napalm_validate.py", line 29, in napalm_validate
    validation_file=src, validation_source=validation_source
  File "/home/gns3/virtualvenvs/nornir/lib/python3.6/site-packages/napalm/base/base.py", line 1676, in compliance_report
    self, validation_file=validation_file, validation_source=validation_source
  File "/home/gns3/virtualvenvs/nornir/lib/python3.6/site-packages/napalm/base/validate.py", line 189, in compliance_report
    validation_source = _get_validation_file(validation_file)
  File "/home/gns3/virtualvenvs/nornir/lib/python3.6/site-packages/napalm/base/validate.py", line 29, in _get_validation_file
    raise ValidationException("File {0} not found.".format(validation_file))
napalm.base.exceptions.ValidationException: File ../validators/validate.yaml not found.

2020-05-06 18:33:03,661 - nornir.core.task -    ERROR -      start() - Host 'r2': task 'napalm_validate' failed with traceback:
Traceback (most recent call last):
  File "/home/gns3/virtualvenvs/nornir/lib/python3.6/site-packages/napalm/base/validate.py", line 23, in _get_validation_file
    with open(validation_file, "r") as stream:
FileNotFoundError: [Errno 2] No such file or directory: '../validators/validate.yaml'

During handling of the above exception, another exception occurred:

Traceback (most recent call last):
  File "/home/gns3/virtualvenvs/nornir/lib/python3.6/site-packages/nornir/core/task.py", line 85, in start
    r = self.task(self, **self.params)
  File "/home/gns3/virtualvenvs/nornir/lib/python3.6/site-packages/nornir/plugins/tasks/networking/napalm_validate.py", line 29, in napalm_validate
    validation_file=src, validation_source=validation_source
  File "/home/gns3/virtualvenvs/nornir/lib/python3.6/site-packages/napalm/base/base.py", line 1676, in compliance_report
    self, validation_file=validation_file, validation_source=validation_source
  File "/home/gns3/virtualvenvs/nornir/lib/python3.6/site-packages/napalm/base/validate.py", line 189, in compliance_report
    validation_source = _get_validation_file(validation_file)
  File "/home/gns3/virtualvenvs/nornir/lib/python3.6/site-packages/napalm/base/validate.py", line 29, in _get_validation_file
    raise ValidationException("File {0} not found.".format(validation_file))
napalm.base.exceptions.ValidationException: File ../validators/validate.yaml not found.

2020-05-06 18:33:40,646 -  nornir.core -     INFO -        run() - Running task 'napalm_validate' with args {'src': '../validators/validate.yaml'} on 2 hosts
2020-05-06 18:33:42,621 - nornir.core.task -    ERROR -      start() - Host 'r1': task 'napalm_validate' failed with traceback:
Traceback (most recent call last):
  File "/home/gns3/virtualvenvs/nornir/lib/python3.6/site-packages/nornir/core/task.py", line 85, in start
    r = self.task(self, **self.params)
  File "/home/gns3/virtualvenvs/nornir/lib/python3.6/site-packages/nornir/plugins/tasks/networking/napalm_validate.py", line 29, in napalm_validate
    validation_file=src, validation_source=validation_source
  File "/home/gns3/virtualvenvs/nornir/lib/python3.6/site-packages/napalm/base/base.py", line 1676, in compliance_report
    self, validation_file=validation_file, validation_source=validation_source
  File "/home/gns3/virtualvenvs/nornir/lib/python3.6/site-packages/napalm/base/validate.py", line 200, in compliance_report
    key = expected_results.pop("_name", "") or getter
AttributeError: 'NoneType' object has no attribute 'pop'

2020-05-06 18:33:44,403 - nornir.core.task -    ERROR -      start() - Host 'r2': task 'napalm_validate' failed with traceback:
Traceback (most recent call last):
  File "/home/gns3/virtualvenvs/nornir/lib/python3.6/site-packages/nornir/core/task.py", line 85, in start
    r = self.task(self, **self.params)
  File "/home/gns3/virtualvenvs/nornir/lib/python3.6/site-packages/nornir/plugins/tasks/networking/napalm_validate.py", line 29, in napalm_validate
    validation_file=src, validation_source=validation_source
  File "/home/gns3/virtualvenvs/nornir/lib/python3.6/site-packages/napalm/base/base.py", line 1676, in compliance_report
    self, validation_file=validation_file, validation_source=validation_source
  File "/home/gns3/virtualvenvs/nornir/lib/python3.6/site-packages/napalm/base/validate.py", line 200, in compliance_report
    key = expected_results.pop("_name", "") or getter
AttributeError: 'NoneType' object has no attribute 'pop'

2020-05-06 18:35:17,093 -  nornir.core -     INFO -        run() - Running task 'napalm_validate' with args {'src': '../validators/validate.yaml'} on 2 hosts
2020-05-06 18:35:18,568 - nornir.core.task -    ERROR -      start() - Host 'r1': task 'napalm_validate' failed with traceback:
Traceback (most recent call last):
  File "/home/gns3/virtualvenvs/nornir/lib/python3.6/site-packages/nornir/core/task.py", line 85, in start
    r = self.task(self, **self.params)
  File "/home/gns3/virtualvenvs/nornir/lib/python3.6/site-packages/nornir/plugins/tasks/networking/napalm_validate.py", line 29, in napalm_validate
    validation_file=src, validation_source=validation_source
  File "/home/gns3/virtualvenvs/nornir/lib/python3.6/site-packages/napalm/base/base.py", line 1676, in compliance_report
    self, validation_file=validation_file, validation_source=validation_source
  File "/home/gns3/virtualvenvs/nornir/lib/python3.6/site-packages/napalm/base/validate.py", line 200, in compliance_report
    key = expected_results.pop("_name", "") or getter
AttributeError: 'NoneType' object has no attribute 'pop'

2020-05-06 18:35:20,229 - nornir.core.task -    ERROR -      start() - Host 'r2': task 'napalm_validate' failed with traceback:
Traceback (most recent call last):
  File "/home/gns3/virtualvenvs/nornir/lib/python3.6/site-packages/nornir/core/task.py", line 85, in start
    r = self.task(self, **self.params)
  File "/home/gns3/virtualvenvs/nornir/lib/python3.6/site-packages/nornir/plugins/tasks/networking/napalm_validate.py", line 29, in napalm_validate
    validation_file=src, validation_source=validation_source
  File "/home/gns3/virtualvenvs/nornir/lib/python3.6/site-packages/napalm/base/base.py", line 1676, in compliance_report
    self, validation_file=validation_file, validation_source=validation_source
  File "/home/gns3/virtualvenvs/nornir/lib/python3.6/site-packages/napalm/base/validate.py", line 200, in compliance_report
    key = expected_results.pop("_name", "") or getter
AttributeError: 'NoneType' object has no attribute 'pop'

2020-05-06 20:57:13,095 -  nornir.core -     INFO -        run() - Running task 'napalm_validate' with args {'src': '../validators/validate.yaml'} on 2 hosts
2020-05-06 21:21:39,965 -  nornir.core -     INFO -        run() - Running task 'napalm_validate' with args {'src': '../validators/validate.yaml'} on 2 hosts
2020-05-06 21:23:13,582 -  nornir.core -     INFO -        run() - Running task 'napalm_validate' with args {'src': '../validators/validate.yaml'} on 2 hosts
